Workbook

Sheet Cover
B2: AI Cloud TCO & Returns Model
B4: Independent build for illustrative/planning use for the benefit of Hosted.ai customers.
B6: What this workbook contains:
B7: 1. Assumptions — every input driving the model, organized by topic. Blue = input you can change.
B8: 2. TCO Build-Up — the $/GPU-hr cost of ownership, split into capex recovery, power/colocation, maintenance, insurance.
B9: 3. Income Statement — 5-year P&L (revenue through net income).
B10: 4. Balance Sheet — 5-year (+ Year 0) balance sheet including a built-in balance check.
B11: 5. Cash Flow — 5-year cash flow statement (operating / investing / financing).
B12: 6. Returns — unlevered project and levered equity cash flows, IRR, NPV, and residual value.
B13: 7. Hosted.ai ROI — always-on Without vs. With Hosted.ai comparison: overcommit-driven revenue uplift, the VRAM-based license fee, and the resulting IRR/NPV delta.
B15: Methodology notes:
B16: - TCO/hr = capex annualized via a capital-recovery factor at the project WACC, plus power/colocation, maintenance, and insurance, all divided by annual GPU-hours delivered at the assumed utilization rate.
... B22: - This build uses a fixed 5-year explicit forecast; extend columns manually for a longer horizon.

Sheet Assumptions
B1: Assumptions
B2: Blue = hardcoded input. Black = calculated. Edit blue cells to run scenarios.
B4: 1. GPU & CLUSTER
B5: GPU / system type | C5: H100
B6: Number of GPUs | C6: 8192
B7: All-in capex per GPU ($) | C7: 33000
B8: IT power draw per GPU (W, all-in) | C8: 1300
B10: 2. POWER & FACILITY COST
B11: Power mode (1=Colocation, 0=Owned facility) | C11: 1
B12: Colocation rate ($/kW-month, all-in) | C12: 180
B13: Electricity rate ($/kWh, owned facility) | C13: 0.08
B14: Facility PUE (owned facility) | C14: 1.3
B16: 3. FINANCING
B17: Debt % of capex | C17: 0.5
B18: All-in debt interest rate | C18: 0.08
B19: Debt term (years) | C19: 5
B21: 4. DEPRECIATION & USEFUL LIFE
B22: Accounting/economic useful life (years) | C22: 5
B23: Residual / salvage value (% of capex) | C23: 0.1
B25: 5. REVENUE & PRICING
B26: Rental price, Year 1 ($/GPU-hr) | C26: 2.5
B27: Steady-state utilization | C27: 0.8
B28: Year-1 ramp (% of steady-state utilization) | C28: 0.8
B29: Annual rental price decline | C29: 0.05
B31: 6. OPEX & TAX
B32: Maintenance / support (% of capex, per yr) | C32: 0.03
B33: Insurance & other (% of capex, per yr) | C33: 0.01
B34: SG&A (% of revenue) | C34: 0.08
B35: Effective tax rate | C35: 0.21
B37: 7. HORIZON & DISCOUNT RATES
B38: Analysis horizon (years, fixed build) | C38: 5
B39: WACC / project discount rate | C39: 0.12
B40: Cost of equity / equity discount rate | C40: 0.18
B42: DERIVED (calculated — do not overwrite)
B43: Total capex ($) | C43: =C6*C7 -> 270336000
B44: Debt amount ($) | C44: =C43*C17 -> 135168000
B45: Equity amount ($) | C45: =C43-C44 -> 135168000
B46: Total IT load (kW) | C46: =C6*C8/1000 -> 10649.6
B47: Annual power/facility cost ($) | C47: =IF(C11=1,C46*C12*12,C46*C14*8760*C13) -> 23003136
B48: Capital recovery factor (CRF) | C48: =C39*(1+C39)^C22/((1+C39)^C22-1) -> 0.27740973
...

Sheet TCO_BuildUp
B1: TCO Build-Up ($ / GPU-hr)
B3: Component | C3: $ / GPU-hr | D3: % of TCO | E3: Annualized ($)
B4: Capex — capital recovery @ WACC | C4: =Assumptions!C49/Assumptions!C82 -> 0.41072436 | D4: =C4/$C$9 -> 0.58473271 | E4: =Assumptions!C49 -> 70738486
B5: Power / colocation | C5: =Assumptions!C47/Assumptions!C82 -> 0.13356164 | D5: =C5/$C$9 -> 0.19014665 | E5: =Assumptions!C47 -> 23003136
B6: Maintenance & support | C6: =Assumptions!C50/Assumptions!C82 -> 0.047089041 | D6: =C6/$C$9 -> 0.067038884 | E6: =Assumptions!C50 -> 8110080
B7: Insurance & other | C7: =Assumptions!C51/Assumptions!C82 -> 0.015696347 | D7: =C7/$C$9 -> 0.022346295 | E7: =Assumptions!C51 -> 2703360
B8: Hosted.ai license fee | C8: =Assumptions!C81/Assumptions!C82 -> 0.095342466 | D8: =C8/$C$9 -> 0.13573546 | E8: =Assumptions!C81 -> 16420700
B9: Total TCO | C9: =SUM(C4:C8) -> 0.70241386 | D9: =C9/$C$9 -> 1 | E9: =SUM(E4:E8) -> 1.2097576e+08
B11: Effective rental price, Year 1 ($/GPU-hr) | C11: =Assumptions!C79 -> 2.625
B12: Gross margin @ list price | C12: =(C11-C9)/C11 -> 0.73241377
B13: Billable GPU-hours/yr (incl. overcommit) | C13: =Assumptions!C82 -> 172228608

Sheet Income_Statement
B1: Income Statement
C3: Year 1 | D3: Year 2 | E3: Year 3 | F3: Year 4 | G3: Year 5
B4: Utilization (effective) | C4: =Assumptions!$C$78*Assumptions!$C$28 -> 0.64 | D4: =Assumptions!$C$78 -> 0.8 | E4: =Assumptions!$C$78 -> 0.8 | F4: =Assumptions!$C$78 -> 0.8 | G4: =Assumptions!$C$78 -> 0.8
B5: Rental price, effective ($/GPU-hr) | C5: =Assumptions!$C$79 -> 2.625 | D5: =C5*(1-Assumptions!$C$29) -> 2.49375 | E5: =D5*(1-Assumptions!$C$29) -> 2.3690625 | F5: =E5*(1-Assumptions!$C$29) -> 2.2506094 | G5: =F5*(1-Assumptions!$C$29) -> 2.1380789
B6: Revenue | C6: =C4*C5*Assumptions!$C$6*8760*Assumptions!$C$76 -> 3.6168008e+08 | D6: =D4*D5*Assumptions!$C$6*8760*Assumptions!$C$76 -> 4.2949509e+08 | E6: =E4*E5*Assumptions!$C$6*8760*Assumptions!$C$76 -> 4.0802034e+08 | F6: =F4*F5*Assumptions!$C$6*8760*Assumptions!$C$76 -> 3.8761932e+08 | G6: =G4*G5*Assumptions!$C$6*8760*Assumptions!$C$76 -> 3.6823835e+08
B7: COGS: power/colo+maint+insur+Hosted.ai | C7: =Assumptions!$C$47+Assumptions!$C$50+Assumptions!$C$51+IF(Assumptions!$C$66=1,MAX(Assumptions!$C$72,Assumptions!$C$75*720*Assumptions!$C$70+Assumptions!$C$75*720*C4*Assumptions!$C$71)*12,0) -> 47519367 | D7: =Assumptions!$C$47+Assumptions!$C$50+Assumptions!$C$51+IF(Assumptions!$C$66=1,MAX(Assumptions!$C$72,Assumptions!$C$75*720*Assumptions!$C$70+Assumptions!$C$75*720*D4*Assumptions!$C$71)*12,0) -> 50237276 | E7: =Assumptions!$C$47+Assumptions!$C$50+Assumptions!$C$51+IF(Assumptions!$C$66=1,MAX(Assumptions!$C$72,Assumptions!$C$75*720*Assumptions!$C$70+Assumptions!$C$75*720*E4*Assumptions!$C$71)*12,0) -> 50237276 | F7: =Assumptions!$C$47+Assumptions!$C$50+Assumptions!$C$51+IF(Assumptions!$C$66=1,MAX(Assumptions!$C$72,Assumptions!$C$75*720*Assumptions!$C$70+Assumptions!$C$75*720*F4*Assumptions!$C$71)*12,0) -> 50237276 | G7: =Assumptions!$C$47+Assumptions!$C$50+Assumptions!$C$51+IF(Assumptions!$C$66=1,MAX(Assumptions!$C$72,Assumptions!$C$75*720*Assumptions!$C$70+Assumptions!$C$75*720*G4*Assumptions!$C$71)*12,0) -> 50237276
B8: Gross Profit | C8: =C6-C7 -> 3.1416071e+08 | D8: =D6-D7 -> 3.7925782e+08 | E8: =E6-E7 -> 3.5778306e+08 | F8: =F6-F7 -> 3.3738204e+08 | G8: =G6-G7 -> 3.1800108e+08
B9: SG&A | C9: =C6*Assumptions!$C$34 -> 28934406 | D9: =D6*Assumptions!$C$34 -> 34359607 | E9: =E6*Assumptions!$C$34 -> 32641627 | F9: =F6*Assumptions!$C$34 -> 31009546 | G9: =G6*Assumptions!$C$34 -> 29459068
B10: EBITDA | C10: =C8-C9 -> 2.852263e+08 | D10: =D8-D9 -> 3.4489821e+08 | E10: =E8-E9 -> 3.2514143e+08 | F10: =F8-F9 -> 3.063725e+08 | G10: =G8-G9 -> 2.8854201e+08
B11: Depreciation & Amortization | C11: =MIN(Assumptions!$C$53,Assumptions!$C$43*(1-Assumptions!$C$23)) -> 48660480 | D11: =MIN(Assumptions!$C$53,Assumptions!$C$43*(1-Assumptions!$C$23)-C11) -> 48660480 | E11: =MIN(Assumptions!$C$53,Assumptions!$C$43*(1-Assumptions!$C$23)-C11-D11) -> 48660480 | F11: =MIN(Assumptions!$C$53,Assumptions!$C$43*(1-Assumptions!$C$23)-C11-D11-E11) -> 48660480 | G11: =MIN(Assumptions!$C$53,Assumptions!$C$43*(1-Assumptions!$C$23)-C11-D11-E11-F11) -> 48660480
B12: EBIT | C12: =C10-C11 -> 2.3656582e+08 | D12: =D10-D11 -> 2.9623773e+08 | E12: =E10-E11 -> 2.7648095e+08 | F12: =F10-F11 -> 2.5771202e+08 | G12: =G10-G11 -> 2.3988153e+08
B13: Interest Expense | C13: =Balance_Sheet!B11*Assumptions!$C$18 -> 10813440 | D13: =Balance_Sheet!C11*Assumptions!$C$18 -> 8650752 | E13: =Balance_Sheet!D11*Assumptions!$C$18 -> 6488064 | F13: =Balance_Sheet!E11*Assumptions!$C$18 -> 4325376 | G13: =Balance_Sheet!F11*Assumptions!$C$18 -> 2162688
B14: EBT | C14: =C12-C13 -> 2.2575238e+08 | D14: =D12-D13 -> 2.8758698e+08 | E14: =E12-E13 -> 2.6999289e+08 | F14: =F12-F13 -> 2.5338664e+08 | G14: =G12-G13 -> 2.3771884e+08
B15: Tax | C15: =MAX(0,C14)*Assumptions!$C$35 -> 47408001 | D15: =MAX(0,D14)*Assumptions!$C$35 -> 60393265 | E15: =MAX(0,E14)*Assumptions!$C$35 -> 56698507 | F15: =MAX(0,F14)*Assumptions!$C$35 -> 53211195 | G15: =MAX(0,G14)*Assumptions!$C$35 -> 49920957
B16: Net Income | C16: =C14-C15 -> 1.7834438e+08 | D16: =D14-D15 -> 2.2719371e+08 | E16: =E14-E15 -> 2.1329438e+08 | F16: =F14-F15 -> 2.0017545e+08 | G16: =G14-G15 -> 1.8779788e+08
B17: memo: Hosted.ai license fee (incl. above) | C17: =IF(Assumptions!$C$66=1,MAX(Assumptions!$C$72,Assumptions!$C$75*720*Assumptions!$C$70+Assumptions!$C$75*720*C4*Assumptions!$C$71)*12,0) -> 13702791 | D17: =IF(Assumptions!$C$66=1,MAX(Assumptions!$C$72,Assumptions!$C$75*720*Assumptions!$C$70+Assumptions!$C$75*720*D4*Assumptions!$C$71)*12,0) -> 16420700 | E17: =IF(Assumptions!$C$66=1,MAX(Assumptions!$C$72,Assumptions!$C$75*720*Assumptions!$C$70+Assumptions!$C$75*720*E4*Assumptions!$C$71)*12,0) -> 16420700 | F17: =IF(Assumptions!$C$66=1,MAX(Assumptions!$C$72,Assumptions!$C$75*720*Assumptions!$C$70+Assumptions!$C$75*720*F4*Assumptions!$C$71)*12,0) -> 16420700 | G17: =IF(Assumptions!$C$66=1,MAX(Assumptions!$C$72,Assumptions!$C$75*720*Assumptions!$C$70+Assumptions!$C$75*720*G4*Assumptions!$C$71)*12,0) -> 16420700

Sheet Balance_Sheet
B1: Balance Sheet
B3: Year 0 | C3: Year 1 | D3: Year 2 | E3: Year 3 | F3: Year 4 | G3: Year 5
B5: ASSETS
B6: 0 | C6: =B6+Cash_Flow!C9 -> 1.9997126e+08 | D6: =C6+Cash_Flow!D9 -> 4.4879185e+08 | E6: =D6+Cash_Flow!E9 -> 6.8371312e+08 | F6: =E6+Cash_Flow!F9 -> 9.0551544e+08 | G6: =F6+Cash_Flow!G9 -> 1.1149402e+09
B7: =Assumptions!C43 -> 270336000 | C7: =B7-Income_Statement!C11 -> 221675520 | D7: =C7-Income_Statement!D11 -> 173015040 | E7: =D7-Income_Statement!E11 -> 124354560 | F7: =E7-Income_Statement!F11 -> 75694080 | G7: =F7-Income_Statement!G11 -> 27033600
B8: =SUM(B6:B7) -> 270336000 | C8: =SUM(C6:C7) -> 4.2164678e+08 | D8: =SUM(D6:D7) -> 6.2180689e+08 | E8: =SUM(E6:E7) -> 8.0806768e+08 | F8: =SUM(F6:F7) -> 9.8120952e+08 | G8: =SUM(G6:G7) -> 1.1419738e+09
B10: LIABILITIES & EQUITY
B11: =Assumptions!C44 -> 135168000 | C11: =B11-IF(1<=Assumptions!$C$19,Assumptions!$C$54,0) -> 108134400 | D11: =C11-IF(2<=Assumptions!$C$19,Assumptions!$C$54,0) -> 81100800 | E11: =D11-IF(3<=Assumptions!$C$19,Assumptions!$C$54,0) -> 54067200 | F11: =E11-IF(4<=Assumptions!$C$19,Assumptions!$C$54,0) -> 27033600 | G11: =F11-IF(5<=Assumptions!$C$19,Assumptions!$C$54,0) -> 0
B12: =Assumptions!C45 -> 135168000 | C12: =B12 -> 135168000 | D12: =C12 -> 135168000 | E12: =D12 -> 135168000 | F12: =E12 -> 135168000 | G12: =F12 -> 135168000
B13: 0 | C13: =B13+Income_Statement!C16 -> 1.7834438e+08 | D13: =C13+Income_Statement!D16 -> 4.0553809e+08 | E13: =D13+Income_Statement!E16 -> 6.1883248e+08 | F13: =E13+Income_Statement!F16 -> 8.1900792e+08 | G13: =F13+Income_Statement!G16 -> 1.0068058e+09
B14: =SUM(B11:B13) -> 270336000 | C14: =SUM(C11:C13) -> 4.2164678e+08 | D14: =SUM(D11:D13) -> 6.2180689e+08 | E14: =SUM(E11:E13) -> 8.0806768e+08 | F14: =SUM(F11:F13) -> 9.8120952e+08 | G14: =SUM(G11:G13) -> 1.1419738e+09
B16: =B8-B14 -> 0 | C16: =C8-C14 -> 0 | D16: =D8-D14 -> 0 | E16: =E8-E14 -> 0 | F16: =F8-F14 -> 0 | G16: =G8-G14 -> 0

Sheet Cash_Flow
B1: Cash Flow Statement
C3: Year 1 | D3: Year 2 | E3: Year 3 | F3: Year 4 | G3: Year 5
B4: Net Income | C4: =Income_Statement!C16 -> 1.7834438e+08 | D4: =Income_Statement!D16 -> 2.2719371e+08 | E4: =Income_Statement!E16 -> 2.1329438e+08 | F4: =Income_Statement!F16 -> 2.0017545e+08 | G4: =Income_Statement!G16 -> 1.8779788e+08
B5: + D&A | C5: =Income_Statement!C11 -> 48660480 | D5: =Income_Statement!D11 -> 48660480 | E5: =Income_Statement!E11 -> 48660480 | F5: =Income_Statement!F11 -> 48660480 | G5: =Income_Statement!G11 -> 48660480
B6: Cash Flow from Operations | C6: =C4+C5 -> 2.2700486e+08 | D6: =D4+D5 -> 2.7585419e+08 | E6: =E4+E5 -> 2.6195486e+08 | F6: =F4+F5 -> 2.4883593e+08 | G6: =G4+G5 -> 2.3645836e+08
B7: Capex (Investing) | C7: 0 | D7: 0 | E7: 0 | F7: 0 | G7: 0
B8: Debt Principal Repayment (Financing) | C8: =-IF(1<=Assumptions!$C$19,Assumptions!$C$54,0) -> -27033600 | D8: =-IF(2<=Assumptions!$C$19,Assumptions!$C$54,0) -> -27033600 | E8: =-IF(3<=Assumptions!$C$19,Assumptions!$C$54,0) -> -27033600 | F8: =-IF(4<=Assumptions!$C$19,Assumptions!$C$54,0) -> -27033600 | G8: =-IF(5<=Assumptions!$C$19,Assumptions!$C$54,0) -> -27033600
B9: Net Change in Cash | C9: =C6+C7+C8 -> 1.9997126e+08 | D9: =D6+D7+D8 -> 2.4882059e+08 | E9: =E6+E7+E8 -> 2.3492126e+08 | F9: =F6+F7+F8 -> 2.2180233e+08 | G9: =G6+G7+G8 -> 2.0942476e+08
B10: Ending Cash Balance (tie to Balance Sheet) | C10: =Balance_Sheet!C6 -> 1.9997126e+08 | D10: =Balance_Sheet!D6 -> 4.4879185e+08 | E10: =Balance_Sheet!E6 -> 6.8371312e+08 | F10: =Balance_Sheet!F6 -> 9.0551544e+08 | G10: =Balance_Sheet!G6 -> 1.1149402e+09

Sheet Returns
B1: Returns — Project & Equity Cash Flow
B3: Year 0 | C3: Year 1 | D3: Year 2 | E3: Year 3 | F3: Year 4 | G3: Year 5
B4: =-Assumptions!C43 -> -270336000 | C4: =Income_Statement!C12*(1-Assumptions!$C$35)+Income_Statement!C11-Cash_Flow!C7 -> 2.3554748e+08 | D4: =Income_Statement!D12*(1-Assumptions!$C$35)+Income_Statement!D11-Cash_Flow!D7 -> 2.8268828e+08 | E4: =Income_Statement!E12*(1-Assumptions!$C$35)+Income_Statement!E11-Cash_Flow!E7 -> 2.6708043e+08 | F4: =Income_Statement!F12*(1-Assumptions!$C$35)+Income_Statement!F11-Cash_Flow!F7 -> 2.5225297e+08 | G4: =Income_Statement!G12*(1-Assumptions!$C$35)+Income_Statement!G11-Cash_Flow!G7+Assumptions!$C$43*Assumptions!$C$23 -> 2.6520049e+08
B5: =-Assumptions!C45 -> -135168000 | C5: =Income_Statement!C16+Income_Statement!C11+Cash_Flow!C8 -> 1.9997126e+08 | D5: =Income_Statement!D16+Income_Statement!D11+Cash_Flow!D8 -> 2.4882059e+08 | E5: =Income_Statement!E16+Income_Statement!E11+Cash_Flow!E8 -> 2.3492126e+08 | F5: =Income_Statement!F16+Income_Statement!F11+Cash_Flow!F8 -> 2.2180233e+08 | G5: =Income_Statement!G16+Income_Statement!G11+Cash_Flow!G8+Assumptions!$C$43*Assumptions!$C$23-Balance_Sheet!G11 -> 2.3645836e+08
B7: =SUM($B$4:B4) -> -270336000 | C7: =SUM($B$4:C4) -> -34788519 | D7: =SUM($B$4:D4) -> 2.4789977e+08 | E7: =SUM($B$4:E4) -> 5.149802e+08 | F7: =SUM($B$4:F4) -> 7.6723317e+08 | G7: =SUM($B$4:G4) -> 1.0324337e+09
B8: =SUM($B$5:B5) -> -135168000 | C8: =SUM($B$5:C5) -> 64803263 | D8: =SUM($B$5:D5) -> 3.1362385e+08 | E8: =SUM($B$5:E5) -> 5.4854512e+08 | F8: =SUM($B$5:F5) -> 7.7034744e+08 | G8: =SUM($B$5:G5) -> 1.0068058e+09
B10: Project IRR (unlevered) | C10: =IFERROR(IRR(B4:G4),"n/a") -> 0.90342259
B11: Equity IRR (levered) | C11: =IFERROR(IRR(B5:G5),"n/a") -> 1.5854932
B12: NPV — Project @ WACC | C12: =B4+NPV(Assumptions!C39,C4:G4) -> 6.662274e+08
B13: NPV — Equity @ Cost of Equity | C13: =B5+NPV(Assumptions!C40,C5:G5) -> 5.7373988e+08
B14: Residual / salvage value at exit | C14: =Assumptions!C43*Assumptions!C23 -> 27033600
B15: Simple payback (project, break-even year) | C15: =IFERROR(MATCH(1,INDEX((C7:G7>=0)*1,0),0),"Beyond horizon") -> 2

Sheet Hosted_ai_ROI
B1: Hosted.ai ROI — Without vs. With Comparison
B2: Always computes both scenarios regardless of the Assumptions!C66 toggle. Capex, financing, D&A, and debt are identical in both — only revenue, pricing, and Hosted.ai fees differ.
C3: Year 1 | D3: Year 2 | E3: Year 3 | F3: Year 4 | G3: Year 5
B4: WITHOUT HOSTED.AI (same utilization as With; no overcommit, no price premium, no license fee)
B5: Utilization (held constant vs. With) | C5: =Assumptions!$C$27*Assumptions!$C$28 -> 0.64 | D5: =Assumptions!$C$27 -> 0.8 | E5: =Assumptions!$C$27 -> 0.8 | F5: =Assumptions!$C$27 -> 0.8 | G5: =Assumptions!$C$27 -> 0.8
B6: Rental price ($/GPU-hr) | C6: =Assumptions!$C$26 -> 2.5 | D6: =C6*(1-Assumptions!$C$29) -> 2.375 | E6: =D6*(1-Assumptions!$C$29) -> 2.25625 | F6: =E6*(1-Assumptions!$C$29) -> 2.1434375 | G6: =F6*(1-Assumptions!$C$29) -> 2.0362656
B7: Revenue | C7: =C5*C6*Assumptions!$C$6*8760 -> 114819072 | D7: =D5*D6*Assumptions!$C$6*8760 -> 136347648 | E7: =E5*E6*Assumptions!$C$6*8760 -> 1.2953027e+08 | F7: =F5*F6*Assumptions!$C$6*8760 -> 1.2305375e+08 | G7: =G5*G6*Assumptions!$C$6*8760 -> 1.1690106e+08
B8: COGS (power/colo+maint+insurance) | C8: =Assumptions!$C$47+Assumptions!$C$50+Assumptions!$C$51 -> 33816576 | D8: =Assumptions!$C$47+Assumptions!$C$50+Assumptions!$C$51 -> 33816576 | E8: =Assumptions!$C$47+Assumptions!$C$50+Assumptions!$C$51 -> 33816576 | F8: =Assumptions!$C$47+Assumptions!$C$50+Assumptions!$C$51 -> 33816576 | G8: =Assumptions!$C$47+Assumptions!$C$50+Assumptions!$C$51 -> 33816576
B9: Gross Profit | C9: =C7-C8 -> 81002496 | D9: =D7-D8 -> 102531072 | E9: =E7-E8 -> 95713690 | F9: =F7-F8 -> 89237176 | G9: =G7-G8 -> 83084489
B10: SG&A | C10: =C7*Assumptions!$C$34 -> 9185525.8 | D10: =D7*Assumptions!$C$34 -> 10907812 | E10: =E7*Assumptions!$C$34 -> 10362421 | F10: =F7*Assumptions!$C$34 -> 9844300.2 | G10: =G7*Assumptions!$C$34 -> 9352085.2
B11: EBITDA | C11: =C9-C10 -> 71816970 | D11: =D9-D10 -> 91623260 | E11: =E9-E10 -> 85351268 | F11: =F9-F10 -> 79392876 | G11: =G9-G10 -> 73732404
B12: D&A (shared — unaffected by Hosted.ai) | C12: =Income_Statement!C11 -> 48660480 | D12: =Income_Statement!D11 -> 48660480 | E12: =Income_Statement!E11 -> 48660480 | F12: =Income_Statement!F11 -> 48660480 | G12: =Income_Statement!G11 -> 48660480
B13: EBIT | C13: =C11-C12 -> 23156490 | D13: =D11-D12 -> 42962780 | E13: =E11-E12 -> 36690788 | F13: =F11-F12 -> 30732396 | G13: =G11-G12 -> 25071924
B14: Interest (shared — unaffected by Hosted.ai) | C14: =Income_Statement!C13 -> 10813440 | D14: =Income_Statement!D13 -> 8650752 | E14: =Income_Statement!E13 -> 6488064 | F14: =Income_Statement!F13 -> 4325376 | G14: =Income_Statement!G13 -> 2162688
B15: EBT | C15: =C13-C14 -> 12343050 | D15: =D13-D14 -> 34312028 | E15: =E13-E14 -> 30202724 | F15: =F13-F14 -> 26407020 | G15: =G13-G14 -> 22909236
B16: Tax | C16: =MAX(0,C15)*Assumptions!$C$35 -> 2592040.6 | D16: =MAX(0,D15)*Assumptions!$C$35 -> 7205525.9 | E16: =MAX(0,E15)*Assumptions!$C$35 -> 6342572.1 | F16: =MAX(0,F15)*Assumptions!$C$35 -> 5545474.2 | G16: =MAX(0,G15)*Assumptions!$C$35 -> 4810939.5
B17: Net Income | C17: =C15-C16 -> 9751009.7 | D17: =D15-D16 -> 27106502 | E17: =E15-E16 -> 23860152 | F17: =F15-F16 -> 20861546 | G17: =G15-G16 -> 18098296
B19: WITH HOSTED.AI (overcommit + price premium + license fee, always on for this block)
B20: Utilization | C20: =Assumptions!$C$27*Assumptions!$C$28 -> 0.64 | D20: =Assumptions!$C$27 -> 0.8 | E20: =Assumptions!$C$27 -> 0.8 | F20: =Assumptions!$C$27 -> 0.8 | G20: =Assumptions!$C$27 -> 0.8
B21: Rental price, effective ($/GPU-hr) | C21: =Assumptions!$C$26*(1+Assumptions!$C$69) -> 2.625 | D21: =C21*(1-Assumptions!$C$29) -> 2.49375 | E21: =D21*(1-Assumptions!$C$29) -> 2.3690625 | F21: =E21*(1-Assumptions!$C$29) -> 2.2506094 | G21: =F21*(1-Assumptions!$C$29) -> 2.1380789
B22: Revenue (incl. overcommit) | C22: =C20*C21*Assumptions!$C$6*8760*Assumptions!$C$68 -> 3.6168008e+08 | D22: =D20*D21*Assumptions!$C$6*8760*Assumptions!$C$68 -> 4.2949509e+08 | E22: =E20*E21*Assumptions!$C$6*8760*Assumptions!$C$68 -> 4.0802034e+08 | F22: =F20*F21*Assumptions!$C$6*8760*Assumptions!$C$68 -> 3.8761932e+08 | G22: =G20*G21*Assumptions!$C$6*8760*Assumptions!$C$68 -> 3.6823835e+08
B23: COGS: power/colo+maint+insur+Hosted.ai | C23: =Assumptions!$C$47+Assumptions!$C$50+Assumptions!$C$51+IF(TRUE(),MAX(Assumptions!$C$72,Assumptions!$C$75*720*Assumptions!$C$70+Assumptions!$C$75*720*C20*Assumptions!$C$71)*12,0) -> 47519367 | D23: =Assumptions!$C$47+Assumptions!$C$50+Assumptions!$C$51+IF(TRUE(),MAX(Assumptions!$C$72,Assumptions!$C$75*720*Assumptions!$C$70+Assumptions!$C$75*720*D20*Assumptions!$C$71)*12,0) -> 50237276 | E23: =Assumptions!$C$47+Assumptions!$C$50+Assumptions!$C$51+IF(TRUE(),MAX(Assumptions!$C$72,Assumptions!$C$75*720*Assumptions!$C$70+Assumptions!$C$75*720*E20*Assumptions!$C$71)*12,0) -> 50237276 | F23: =Assumptions!$C$47+Assumptions!$C$50+Assumptions!$C$51+IF(TRUE(),MAX(Assumptions!$C$72,Assumptions!$C$75*720*Assumptions!$C$70+Assumptions!$C$75*720*F20*Assumptions!$C$71)*12,0) -> 50237276 | G23: =Assumptions!$C$47+Assumptions!$C$50+Assumptions!$C$51+IF(TRUE(),MAX(Assumptions!$C$72,Assumptions!$C$75*720*Assumptions!$C$70+Assumptions!$C$75*720*G20*Assumptions!$C$71)*12,0) -> 50237276
B24: Gross Profit | C24: =C22-C23 -> 3.1416071e+08 | D24: =D22-D23 -> 3.7925782e+08 | E24: =E22-E23 -> 3.5778306e+08 | F24: =F22-F23 -> 3.3738204e+08 | G24: =G22-G23 -> 3.1800108e+08
B25: SG&A | C25: =C22*Assumptions!$C$34 -> 28934406 | D25: =D22*Assumptions!$C$34 -> 34359607 | E25: =E22*Assumptions!$C$34 -> 32641627 | F25: =F22*Assumptions!$C$34 -> 31009546 | G25: =G22*Assumptions!$C$34 -> 29459068
B26: EBITDA | C26: =C24-C25 -> 2.852263e+08 | D26: =D24-D25 -> 3.4489821e+08 | E26: =E24-E25 -> 3.2514143e+08 | F26: =F24-F25 -> 3.063725e+08 | G26: =G24-G25 -> 2.8854201e+08
B27: D&A (shared — unaffected by Hosted.ai) | C27: =Income_Statement!C11 -> 48660480 | D27: =Income_Statement!D11 -> 48660480 | E27: =Income_Statement!E11 -> 48660480 | F27: =Income_Statement!F11 -> 48660480 | G27: =Income_Statement!G11 -> 48660480
B28: EBIT | C28: =C26-C27 -> 2.3656582e+08 | D28: =D26-D27 -> 2.9623773e+08 | E28: =E26-E27 -> 2.7648095e+08 | F28: =F26-F27 -> 2.5771202e+08 | G28: =G26-G27 -> 2.3988153e+08
B29: Interest (shared — unaffected by Hosted.ai) | C29: =Income_Statement!C13 -> 10813440 | D29: =Income_Statement!D13 -> 8650752 | E29: =Income_Statement!E13 -> 6488064 | F29: =Income_Statement!F13 -> 4325376 | G29: =Income_Statement!G13 -> 2162688
B30: EBT | C30: =C28-C29 -> 2.2575238e+08 | D30: =D28-D29 -> 2.8758698e+08 | E30: =E28-E29 -> 2.6999289e+08 | F30: =F28-F29 -> 2.5338664e+08 | G30: =G28-G29 -> 2.3771884e+08
B31: Tax | C31: =MAX(0,C30)*Assumptions!$C$35 -> 47408001 | D31: =MAX(0,D30)*Assumptions!$C$35 -> 60393265 | E31: =MAX(0,E30)*Assumptions!$C$35 -> 56698507 | F31: =MAX(0,F30)*Assumptions!$C$35 -> 53211195 | G31: =MAX(0,G30)*Assumptions!$C$35 -> 49920957
B32: Net Income | C32: =C30-C31 -> 1.7834438e+08 | D32: =D30-D31 -> 2.2719371e+08 | E32: =E30-E31 -> 2.1329438e+08 | F32: =F30-F31 -> 2.0017545e+08 | G32: =G30-G31 -> 1.8779788e+08
B33: memo: Hosted.ai license fee (incl. above) | C33: =IF(TRUE(),MAX(Assumptions!$C$72,Assumptions!$C$75*720*Assumptions!$C$70+Assumptions!$C$75*720*C20*Assumptions!$C$71)*12,0) -> 13702791 | D33: =IF(TRUE(),MAX(Assumptions!$C$72,Assumptions!$C$75*720*Assumptions!$C$70+Assumptions!$C$75*720*D20*Assumptions!$C$71)*12,0) -> 16420700 | E33: =IF(TRUE(),MAX(Assumptions!$C$72,Assumptions!$C$75*720*Assumptions!$C$70+Assumptions!$C$75*720*E20*Assumptions!$C$71)*12,0) -> 16420700 | F33: =IF(TRUE(),MAX(Assumptions!$C$72,Assumptions!$C$75*720*Assumptions!$C$70+Assumptions!$C$75*720*F20*Assumptions!$C$71)*12,0) -> 16420700 | G33: =IF(TRUE(),MAX(Assumptions!$C$72,Assumptions!$C$75*720*Assumptions!$C$70+Assumptions!$C$75*720*G20*Assumptions!$C$71)*12,0) -> 16420700
B35: PROJECT & EQUITY CASH FLOWS
B36: Year 0 | C36: Year 1 | D36: Year 2 | E36: Year 3 | F36: Year 4 | G36: Year 5
B37: =-Assumptions!C43 -> -270336000 | C37: =C13*(1-Assumptions!$C$35)+C12 -> 66954107 | D37: =D13*(1-Assumptions!$C$35)+D12 -> 82601076 | E37: =E13*(1-Assumptions!$C$35)+E12 -> 77646203 | F37: =F13*(1-Assumptions!$C$35)+F12 -> 72939073 | G37: =G13*(1-Assumptions!$C$35)+G12+Assumptions!$C$43*Assumptions!$C$23 -> 95500900
B38: =-Assumptions!C43 -> -270336000 | C38: =C28*(1-Assumptions!$C$35)+C27 -> 2.3554748e+08 | D38: =D28*(1-Assumptions!$C$35)+D27 -> 2.8268828e+08 | E38: =E28*(1-Assumptions!$C$35)+E27 -> 2.6708043e+08 | F38: =F28*(1-Assumptions!$C$35)+F27 -> 2.5225297e+08 | G38: =G28*(1-Assumptions!$C$35)+G27+Assumptions!$C$43*Assumptions!$C$23 -> 2.6520049e+08
B39: =-Assumptions!C45 -> -135168000 | C39: =C17+C12+Cash_Flow!C8 -> 31377890 | D39: =D17+D12+Cash_Flow!D8 -> 48733382 | E39: =E17+E12+Cash_Flow!E8 -> 45487032 | F39: =F17+F12+Cash_Flow!F8 -> 42488426 | G39: =G17+G12+Cash_Flow!G8+Assumptions!$C$43*Assumptions!$C$23-Balance_Sheet!G11 -> 66758776
B40: =-Assumptions!C45 -> -135168000 | C40: =C32+C27+Cash_Flow!C8 -> 1.9997126e+08 | D40: =D32+D27+Cash_Flow!D8 -> 2.4882059e+08 | E40: =E32+E27+Cash_Flow!E8 -> 2.3492126e+08 | F40: =F32+F27+Cash_Flow!F8 -> 2.2180233e+08 | G40: =G32+G27+Cash_Flow!G8+Assumptions!$C$43*Assumptions!$C$23-Balance_Sheet!G11 -> 2.3645836e+08
B41: =SUM($B$37:B37) -> -270336000 | C41: =SUM($B$37:C37) -> -2.0338189e+08 | D41: =SUM($B$37:D37) -> -1.2078082e+08 | E41: =SUM($B$37:E37) -> -43134614 | F41: =SUM($B$37:F37) -> 29804459 | G41: =SUM($B$37:G37) -> 1.2530536e+08
B42: =SUM($B$38:B38) -> -270336000 | C42: =SUM($B$38:C38) -> -34788519 | D42: =SUM($B$38:D38) -> 2.4789977e+08 | E42: =SUM($B$38:E38) -> 5.149802e+08 | F42: =SUM($B$38:F38) -> 7.6723317e+08 | G42: =SUM($B$38:G38) -> 1.0324337e+09
...
